Workbook

Sheet Instructions
A1: POST-DISBURSEMENT END-USE OF FUNDS (EUF) MONITORING — LAP / HOME LOAN
A3: Purpose
A4: This workbook tracks whether loan proceeds have been utilised for the sanctioned purpose, in line with RBI's Fair Practices Code / KYC Master Direction expectations on monitoring end use of funds for secured retail loans (Loan Against Property and Home Loan). It should be updated by the Credit/Monitoring team after each disbursement tranche and at each periodic review (typically 30/60/90 days post-disbursement, and at each construction-linked tranche for Home Loans).
A10: Sheet | B10: What it captures | C10: Who updates it
A11: Loan Master | B11: Borrower, property/asset and sanction details | C11: Credit / Ops team, at sanction
A12: End-Use Declaration | B12: Purpose-wise break-up of sanctioned amount as declared by borrower | C12: RM / Credit team, at sanction
A13: Disbursement Register | B13: Tranche-wise disbursement — date, amount, mode, payee | C13: Disbursement / Ops team
A14: Txn Register (Auto) | B14: Every post-disbursement bank transaction, auto-classified | C14: Auto-generated by the Python script
A15: Utilisation Summary | B15: Category-wise utilisation vs sanctioned end-use, with variance | C15: Auto-generated (formulas) — review manually
A16: Diversion Red-Flag Log | B16: Transactions breaching diversion-risk rules, for investigation | C16: Monitoring team — mandatory sign-off
A17: Site Visit & Verification | B17: Physical verification checklist (property stage / business use) | C17: Field / Credit team
A18: Utilisation Certificate | B18: Final certificate for the credit file / auditor / RBI inspection | C18: Credit Head — signs off
A19: Dashboard | B19: One-page summary of utilisation %, flags and status | C19: Auto-generated
A22: Legend
B23: Yellow fill — cell you should fill in / edit manually
B24: Red fill — red-flagged / not permitted for declared end use
B25: Green fill — verified / permitted / within tolerance

Sheet Loan Master
A1: LOAN MASTER DATA
A3: Borrower Name | B3: [Borrower Name — from KYC]
A4: Loan / Account Number | B4: [LAN — Loan Account Number]
A5: Loan Type | B5: LAP
A6: Sanctioned Amount (Rs.) | B6: 892242
A7: Sanction Date
A8: Disbursement Date (auto-detected) | B8: 46129
A9: Disbursed Amount (auto-detected) | B9: 892242
A10: Lender / NBFC | B10: SBFC
A11: Declared Purpose | B11: Business expansion / working capital (LAP)
A12: Property / Asset Address (LAP collateral or HL property) | B12: [Mortgaged property address]
A13: Monitoring Window (days) | B13: 90
A14: Monitoring Window End Date | B14: 46219
A15: Prepared By
A16: Date Prepared | B16: 46213
A18: Note: Rows filled yellow are inputs — edit for each loan file. Disbursement date/amount are auto-detected from the bank statement by the Python script (engine matches the credit closest to the sanctioned amount).

Sheet End-Use Declaration
A1: SANCTIONED END-USE DECLARATION
A3: Purpose-wise break-up of the sanctioned amount, as declared by the borrower at login/sanction. This is the baseline the actual utilisation (Utilisation Summary sheet) is compared against.
A5: Declared End-Use Head | B5: % of Sanctioned Amount | C5: Amount (Rs.) | D5: Supporting Document Required
A6: Business working capital | B6: 0.5 | C6: =B6*'Loan Master'!$B$6 -> 446121 | D6: GST returns / stock statement to be obtained
A7: Business expansion / capex | B7: 0.25 | C7: =B7*'Loan Master'!$B$6 -> 223060.5 | D7: Invoice-backed disbursement preferred
A8: Existing high-cost debt consolidation | B8: 0.15 | C8: =B8*'Loan Master'!$B$6 -> 133836.3 | D8: Closure proof from other lender required
A9: Working capital buffer / contingency | B9: 0.1 | C9: =B9*'Loan Master'!$B$6 -> 89224.2
A10: TOTAL | B10: =SUM(B6:B9) -> 1 | C10: =SUM(C6:C9) -> 892242

Sheet Disbursement Register
A1: TRANCHE-WISE DISBURSEMENT REGISTER
A3: Tranche # | B3: Disbursement Date | C3: Amount (Rs.) | D3: Mode | E3: Paid To (Beneficiary) | F3: Beneficiary Type | G3: Linked Milestone / Invoice Ref. | H3: Cumulative % of Sanction
A4: 1 | B4: 46129 | C4: 892242 | D4: NEFT | E4: Borrower operative a/c | F4: Direct / Third-Party | G4: Auto-detected from bank statement — verify against sanction letter | H4: =C4/'Loan Master'!$B$6 -> 1
H5: =SUM($C$4:C5)/'Loan Master'!$B$6 -> 1
H6: =SUM($C$4:C6)/'Loan Master'!$B$6 -> 1
H7: =SUM($C$4:C7)/'Loan Master'!$B$6 -> 1

Sheet Txn Register (Auto)
A1: POST-DISBURSEMENT TRANSACTION REGISTER (AUTO-CLASSIFIED)
A3: Generated by end_use_engine.py from the borrower's bank statement. Every debit/credit from the disbursement date onward is classified into an End-Use Bucket and checked against automated diversion-risk rules. Do not hand-edit — rerun the script instead.
A5: Date | B5: Mode | C5: Amount | D5: Cr/Dr | E5: Narration | F5: Counterparty | G5: Bank Category | H5: End-Use Bucket | I5: Permitted? | J5: Risk Level | K5: Days from Disbursement | L5: Red Flag | M5: Flag Reason
A6: 46129 | B6: NEFT | C6: 892242 | D6: CREDIT | E6: NEFT/IN22610720970564/SBFC FINANCE LIMITED | F6: IN222 | G6: Direct Deposit | H6: Incoming Funds / Not Applicable | I6: N/A | J6: Low | K6: 0 | L6: =FALSE() -> FALSE
A7: 46129 | B7: UPI | C7: 35000 | D7: DEBIT | E7: UPI/DR/591270732264/KANHAIYA/IDFB/626336007@AXL/PA | F7: Kanhaiya | G7: External Transfers | H7: Third-Party Transfer (Unverified) | I7: Review | J7: Medium | K7: 0 | L7: =FALSE() -> FALSE
A8: 46129 | B8: UPI | C8: 10 | D8: DEBIT | E8: UPI/DR/610758339994/SAFE GOL/YESB/SAFEGOLD@YBL/GOL | F8: SAFE GOL | G8: Gold | H8: Investment / Gold Purchase | I8: N | J8: High | K8: 0 | L8: =FALSE() -> FALSE
A9: 46129 | B9: UPI | C9: 30000 | D9: DEBIT | E9: UPI/DR/905286625164/HEMANT K/HDFC/HEMANTKARMA245@/ | F9: HEMANT K | G9: External Transfers | H9: Third-Party Transfer (Unverified) | I9: Review | J9: Medium | K9: 0 | L9: =FALSE() -> FALSE
A10: 46129 | B10: UPI | C10: 300 | D10: CREDIT | E10: UPI/CR/291949906977/SOHAN KO/INDB/7869627131@AXL/P | F10: SOHAN KO | G10: Direct Deposit | H10: Incoming Funds / Not Applicable | I10: N/A | J10: Low | K10: 0 | L10: =FALSE() -> FALSE
A11: 46129 | B11: UPI | C11: 300 | D11: DEBIT | E11: UPI/DR/628025179050/ANITA P/SBIN/9301011271@YBL/P | F11: Anita P | G11: External Transfers | H11: Third-Party Transfer (Unverified) | I11: Review | J11: Medium | K11: 0 | L11: =FALSE() -> FALSE
A12: 46129 | B12: UPI | C12: 200 | D12: DEBIT | E12: UPI/DR/610709556635/SARASWAT/FDRL/BHARATPE.900683/ | F12: SARASWAT | G12: External Transfers | H12: Third-Party Transfer (Unverified) | I12: Review | J12: Medium | K12: 0 | L12: =FALSE() -> FALSE
A13: 46129 | B13: CASH | C13: 200000 | D13: DEBIT | E13: TO SELF | F13: SELF | G13: Cash Withdrawals | H13: Cash Withdrawal | I13: N | J13: High | K13: 0 | L13: =TRUE() -> TRUE | M13: Cash withdrawal = 22.4% of loan amount; Single debit = 22.4% of loan amount (>10% threshold); Large outflow within 24 hrs of disbursement
A14: 46129 | B14: UPI | C14: 410 | D14: DEBIT | E14: UPI/DR/610709723435/RAHUL/SBIN/9981644788@IBL/UPI | F14: Rahul | G14: External Transfers | H14: Third-Party Transfer (Unverified) | I14: Review | J14: Medium | K14: 0 | L14: =FALSE() -> FALSE
A15: 46129 | B15: UPI | C15: 260 | D15: DEBIT | E15: UPI/DR/610709966414/MALVIYA/YESB/Q853718356@YBL/UP | F15: MALVIYA | G15: External Transfers | H15: Third-Party Transfer (Unverified) | I15: Review | J15: Medium | K15: 0 | L15: =FALSE() -> FALSE
A16: 46130 | B16: UPI | C16: 500 | D16: DEBIT | E16: UPI/DR/610810272579/ARIHA AU/YESB/Q388550272@YBL/U | F16: ARIHA AU | G16: External Transfers | H16: Third-Party Transfer (Unverified) | I16: Review | J16: Medium | K16: 1 | L16: =FALSE() -> FALSE
A17: 46130 | B17: UPI | C17: 830 | D17: DEBIT | E17: UPI/DR/869615012740/ANSHUL/SBIN/Q99692270@YBL/PAYM | F17: ANSHUL | G17: External Transfers | H17: Third-Party Transfer (Unverified) | I17: Review | J17: Medium | K17: 1 | L17: =FALSE() -> FALSE
A18: 46130 | B18: UPI | C18: 3900 | D18: DEBIT | E18: UPI/DR/251562417758/KAPIL PA/YESB/PAYTM.S1GY7Y1@P/ | F18: KAPIL PA | G18: External Transfers | H18: Third-Party Transfer (Unverified) | I18: Review | J18: Medium | K18: 1 | L18: =FALSE() -> FALSE
A19: 46130 | B19: UPI | C19: 24000 | D19: DEBIT | E19: UPI/DR/247219980933/HEMANT K/HDFC/HEMANTKARMA245@/ | F19: HEMANT K | G19: External Transfers | H19: Third-Party Transfer (Unverified) | I19: Review | J19: Medium | K19: 1 | L19: =FALSE() -> FALSE
A20: 46130 | B20: UPI | C20: 4200 | D20: DEBIT | E20: UPI/DR/216863829835/SUBHASH/BKID/9893534340@AXL/PA | F20: SUBHASH | G20: External Transfers | H20: Third-Party Transfer (Unverified) | I20: Review | J20: Medium | K20: 1 | L20: =FALSE() -> FALSE
A21: 46130 | B21: UPI | C21: 10 | D21: DEBIT | E21: UPI/DR/610889265619/SAFE GOL/YESB/SAFEGOLD@YBL/GOL | F21: SAFE GOL | G21: Gold | H21: Investment / Gold Purchase | I21: N | J21: High | K21: 1 | L21: =FALSE() -> FALSE
A22: 46130 | B22: UPI | C22: 30000 | D22: DEBIT | E22: UPI/DR/412110031216/KANHAIYA/IDFB/626336007@AXL/PA | F22: Kanhaiya | G22: External Transfers | H22: Third-Party Transfer (Unverified) | I22: Review | J22: Medium | K22: 1 | L22: =FALSE() -> FALSE
A23: 46130 | B23: UPI | C23: 5 | D23: DEBIT | E23: UPI/DR/610810582141/AMAR SHI/YESB/Q204840053@YBL/U | F23: AMAR SHI | G23: External Transfers | H23: Third-Party Transfer (Unverified) | I23: Review | J23: Medium | K23: 1 | L23: =FALSE() -> FALSE
A24: 46130 | B24: UPI | C24: 20000 | D24: DEBIT | E24: UPI/DR/534138015018/KAMAL S/SBIN/9575114784@YBL/P | F24: KAMAL S | G24: External Transfers | H24: Third-Party Transfer (Unverified) | I24: Review | J24: Medium | K24: 1 | L24: =FALSE() -> FALSE
A25: 46130 | B25: UPI | C25: 700 | D25: DEBIT | E25: UPI/DR/610810990073/SAI GARM/HDFC/SAIGARMENTS.630/ | F25: SAI GARM | G25: External Transfers | H25: Third-Party Transfer (Unverified) | I25: Review | J25: Medium | K25: 1 | L25: =FALSE() -> FALSE
... A29: 46131 | B29: UPI | C29: 30000 | D29: DEBIT | E29: UPI/DR/794396557997/YASHVANT/BARB/YASHBHAYAL14200/ | F29: YASHVANT | G29: External Transfers | H29: Third-Party Transfer (Unverified) | I29: Review | J29: Medium | K29: 2 | L29: =FALSE() -> FALSE
A30: 46131 | B30: IMPS | C30: 50000 | D30: DEBIT | E30: IMPS-OUT/610908326936/SBIN0030223/35400297292 | G30: External Transfers | H30: Third-Party Transfer (Unverified) | I30: Review | J30: Medium | K30: 2 | L30: =FALSE() -> FALSE
A31: 46131 | B31: UPI | C31: 30 | D31: DEBIT | E31: UPI/DR/610912389139/MR MANSH/YESB/PAYTMQR28100505/ | F31: Mr Mansh | G31: External Transfers | H31: Third-Party Transfer (Unverified) | I31: Review | J31: Medium | K31: 2 | L31: =FALSE() -> FALSE
A32: 46131 | B32: UPI | C32: 40 | D32: DEBIT | E32: UPI/DR/610912402066/M M CHOP/IDFB/Q642124650@YBL/U | F32: M M CHOP | G32: External Transfers | H32: Third-Party Transfer (Unverified) | I32: Review | J32: Medium | K32: 2 | L32: =FALSE() -> FALSE
A33: 46131 | B33: UPI | C33: 7954 | D33: DEBIT | E33: UPI/DR/461437058861/MR NITIN/CBIN/6261221618@AXL/P | F33: Mr NITIN | G33: External Transfers | H33: Third-Party Transfer (Unverified) | I33: Review | J33: Medium | K33: 2 | L33: =FALSE() -> FALSE
A34: 46131 | B34: UPI | C34: 50 | D34: DEBIT | E34: UPI/DR/610912377842/M M CHOP/IDFB/Q110060102@YBL/U | F34: M M CHOP | G34: External Transfers | H34: Third-Party Transfer (Unverified) | I34: Review | J34: Medium | K34: 2 | L34: =FALSE() -> FALSE
A35: 46131 | B35: UPI | C35: 10000 | D35: DEBIT | E35: UPI/DR/546242385266/SANJAY M/AUBL/9144757777-2@AX/ | F35: Sanjay M | G35: External Transfers | H35: Third-Party Transfer (Unverified) | I35: Review | J35: Medium | K35: 2 | L35: =FALSE() -> FALSE
A36: 46131 | B36: UPI | C36: 10 | D36: DEBIT | E36: UPI/DR/610915810566/SAFE GOL/YESB/SAFEGOLD@YBL/GOL | F36: SAFE GOL | G36: Gold | H36: Investment / Gold Purchase | I36: N | J36: High | K36: 2 | L36: =FALSE() -> FALSE
A37: 46131 | B37: UPI | C37: 12000 | D37: DEBIT | E37: UPI/DR/967102070851/MR NITIN/CBIN/6261221618@IBL/P | F37: Mr NITIN | G37: External Transfers | H37: Third-Party Transfer (Unverified) | I37: Review | J37: Medium | K37: 2 | L37: =FALSE() -> FALSE
A38: 46131 | B38: UPI | C38: 50 | D38: DEBIT | E38: UPI/DR/610911563060/M M CHOP/IDFB/Q110060102@YBL/U | F38: M M CHOP | G38: External Transfers | H38: Third-Party Transfer (Unverified) | I38: Review | J38: Medium | K38: 2 | L38: =FALSE() -> FALSE
A39: 46131 | B39: IMPS | C39: 5.9 | D39: DEBIT | E39: IMPS-CHG/610908326936/SBIN0030223/35400297292 | G39: Bank Fees and Charges | H39: Bank Charges | I39: N/A | J39: Low | K39: 2 | L39: =FALSE() -> FALSE
A40: 46131 | B40: UPI | C40: 2000 | D40: DEBIT | E40: UPI/DR/338027357108/NEERAJ P/HDFC/6261226303-2@AX/ | F40: NEERAJ P | G40: External Transfers | H40: Third-Party Transfer (Unverified) | I40: Review | J40: Medium | K40: 2 | L40: =FALSE() -> FALSE
A41: 46131 | B41: UPI | C41: 65 | D41: DEBIT | E41: UPI/DR/610911493998/VIRENDRA/YESB/Q750294882@YBL/U | F41: VIRENDRA | G41: External Transfers | H41: Third-Party Transfer (Unverified) | I41: Review | J41: Medium | K41: 2 | L41: =FALSE() -> FALSE
A42: 46131 | B42: UPI | C42: 850 | D42: DEBIT | E42: UPI/DR/753411070238/HARISH B/SBIN/9893287789@AXL/P | F42: HARISH B | G42: External Transfers | H42: Third-Party Transfer (Unverified) | I42: Review | J42: Medium | K42: 2 | L42: =FALSE() -> FALSE
A43: 46132 | B43: UPI | C43: 30 | D43: DEBIT | E43: UPI/DR/611013378548/GANESH S/YESB/Q687840755@YBL/U | F43: GANESH S | G43: External Transfers | H43: Third-Party Transfer (Unverified) | I43: Review | J43: Medium | K43: 3 | L43: =FALSE() -> FALSE
A44: 46132 | B44: ATM | C44: 6000 | D44: DEBIT | E44: ATM WDR 611018022316 ANJAD DISTT BARWANI \ | F44: ATM WDR ANJAD DISTT BARWANI | G44: Cash Withdrawals | H44: Cash Withdrawal | I44: N | J44: High | K44: 3 | L44: =FALSE() -> FALSE
A45: 46132 | B45: UPI | C45: 5500 | D45: CREDIT | E45: UPI/CR/448301650198/RAHUL PA/BKID/7697678766@AXL/P | F45: RAHUL PA | G45: Direct Deposit | H45: Incoming Funds / Not Applicable | I45: N/A | J45: Low | K45: 3 | L45: =FALSE() -> FALSE
...

Sheet Utilisation Summary
A1: END-USE UTILISATION SUMMARY (POST-DISBURSEMENT WINDOW)
A3: Disbursed Amount (Rs.) | B3: ='Loan Master'!B9 -> 892242
A4: Monitoring Window | B4: =TEXT('Loan Master'!B8,"dd-mmm-yyyy")&" to "&TEXT('Loan Master'!B14,"dd-mmm-yyyy") -> 17-Apr-2026 to 16-Jul-2026
A6: End-Use Bucket | B6: Total Amount (Rs.) | C6: Txn Count | D6: % of Disbursed Amount | E6: Assessment
A7: Bank Charges | B7: =SUMIFS('Txn Register (Auto)'!$C:$C,'Txn Register (Auto)'!$H:$H,"Bank Charges",'Txn Register (Auto)'!$D:$D,"DEBIT") -> 5.9 | C7: =COUNTIFS('Txn Register (Auto)'!$H:$H,"Bank Charges",'Txn Register (Auto)'!$D:$D,"DEBIT") -> 1 | D7: =B7/$B$3 -> 6.6125558e-06 | E7: =IF(B7=0,"-",IF(D7>0.1,"Review — material outflow","OK")) -> OK
A8: Cash Withdrawal | B8: =SUMIFS('Txn Register (Auto)'!$C:$C,'Txn Register (Auto)'!$H:$H,"Cash Withdrawal",'Txn Register (Auto)'!$D:$D,"DEBIT") -> 226000 | C8: =COUNTIFS('Txn Register (Auto)'!$H:$H,"Cash Withdrawal",'Txn Register (Auto)'!$D:$D,"DEBIT") -> 4 | D8: =B8/$B$3 -> 0.25329451 | E8: =IF(B8=0,"-",IF(D8>0.1,"Review — material outflow","OK")) -> Review — material outflow
A9: Debt Servicing (Existing Loans) | B9: =SUMIFS('Txn Register (Auto)'!$C:$C,'Txn Register (Auto)'!$H:$H,"Debt Servicing (Existing Loans)",'Txn Register (Auto)'!$D:$D,"DEBIT") -> 55152 | C9: =COUNTIFS('Txn Register (Auto)'!$H:$H,"Debt Servicing (Existing Loans)",'Txn Register (Auto)'!$D:$D,"DEBIT") -> 6 | D9: =B9/$B$3 -> 0.061812827 | E9: =IF(B9=0,"-",IF(D9>0.1,"Review — material outflow","OK")) -> OK
A10: Household / Personal Spend | B10: =SUMIFS('Txn Register (Auto)'!$C:$C,'Txn Register (Auto)'!$H:$H,"Household / Personal Spend",'Txn Register (Auto)'!$D:$D,"DEBIT") -> 2130.18 | C10: =COUNTIFS('Txn Register (Auto)'!$H:$H,"Household / Personal Spend",'Txn Register (Auto)'!$D:$D,"DEBIT") -> 5 | D10: =B10/$B$3 -> 0.0023874465 | E10: =IF(B10=0,"-",IF(D10>0.1,"Review — material outflow","OK")) -> OK
A11: Incoming Funds / Not Applicable | B11: =SUMIFS('Txn Register (Auto)'!$C:$C,'Txn Register (Auto)'!$H:$H,"Incoming Funds / Not Applicable",'Txn Register (Auto)'!$D:$D,"DEBIT") -> 0 | C11: =COUNTIFS('Txn Register (Auto)'!$H:$H,"Incoming Funds / Not Applicable",'Txn Register (Auto)'!$D:$D,"DEBIT") -> 0 | D11: =B11/$B$3 -> 0 | E11: =IF(B11=0,"-",IF(D11>0.1,"Review — material outflow","OK")) -> -
A12: Investment / Gold Purchase | B12: =SUMIFS('Txn Register (Auto)'!$C:$C,'Txn Register (Auto)'!$H:$H,"Investment / Gold Purchase",'Txn Register (Auto)'!$D:$D,"DEBIT") -> 660 | C12: =COUNTIFS('Txn Register (Auto)'!$H:$H,"Investment / Gold Purchase",'Txn Register (Auto)'!$D:$D,"DEBIT") -> 57 | D12: =B12/$B$3 -> 0.00073970963 | E12: =IF(B12=0,"-",IF(D12>0.1,"Review — material outflow","OK")) -> OK
A13: Third-Party Transfer (Unverified) | B13: =SUMIFS('Txn Register (Auto)'!$C:$C,'Txn Register (Auto)'!$H:$H,"Third-Party Transfer (Unverified)",'Txn Register (Auto)'!$D:$D,"DEBIT") -> 662642.82 | C13: =COUNTIFS('Txn Register (Auto)'!$H:$H,"Third-Party Transfer (Unverified)",'Txn Register (Auto)'!$D:$D,"DEBIT") -> 264 | D13: =B13/$B$3 -> 0.74267163 | E13: =IF(B13=0,"-",IF(D13>0.1,"Review — material outflow","OK")) -> Review — material outflow
A14: TOTAL DEBITED | B14: =SUM(B7:B13) -> 946590.9 | C14: =SUM(C7:C13) -> 337 | D14: =B14/$B$3 -> 1.0609127
A16: Note: 'Third-Party Transfer (Unverified)' and 'Debt Servicing' buckets are marked 'Review' by default — obtain invoices/purpose narration from the borrower before closing the file; they are not automatically treated as diversion.

Sheet Diversion Red-Flag Log
A1: DIVERSION / RED-FLAG REGISTER — REQUIRES INVESTIGATION & SIGN-OFF
A3: Date | B3: Amount | C3: Cr/Dr | D3: Narration | E3: Counterparty | F3: Flag Reason | G3: Investigated By | H3: Borrower Explanation | I3: Status
A4: 46129 | B4: 200000 | C4: DEBIT | D4: TO SELF | E4: SELF | F4: Cash withdrawal = 22.4% of loan amount; Single debit = 22.4% of loan amount (>10% threshold); Large outflow within 24 hrs of disbursement | I4: Open

Sheet Site Visit & Verification
A1: SITE VISIT / PHYSICAL VERIFICATION CHECKLIST
A3: # | B3: Verification Point | C3: Verified (Y/N) | D3: Verified By | E3: Date | F3: Remarks
A4: 1 | B4: Mortgaged property physically verified — exists, matches title documents
A5: 2 | B5: Declared business/use of funds is operational at the stated address
A6: 3 | B6: Business registration / GST / trade license verified where applicable
A7: 4 | B7: No signs the property or business is non-existent / shell in nature
A8: 5 | B8: Photographs of property/business premises taken and filed
A9: 6 | B9: Utilisation broadly consistent with the declared end-use (per Utilisation Summary)
A10: 7 | B10: No adverse market intelligence on borrower / co-obligors

Sheet Utilisation Certificate
A1: CERTIFICATE OF END-USE VERIFICATION
A3: This is to certify that the post-disbursement end-use of funds review for the loan account referenced below has been carried out based on a review of the borrower's bank statement, supporting documents and (where applicable) physical/site verification.
A5: Borrower Name: | B5: ='Loan Master'!B3 -> [Borrower Name — from KYC]
A6: Loan / Account Number: | B6: ='Loan Master'!B4 -> [LAN — Loan Account Number]
A7: Sanctioned Amount: | B7: ='Loan Master'!B6 -> 892242
A8: Disbursed Amount: | B8: ='Loan Master'!B9 -> 892242
A9: Disbursement Date: | B9: ='Loan Master'!B8 -> 46129
A10: Declared Purpose: | B10: ='Loan Master'!B11 -> Business expansion / working capital (LAP)
A12: Total Utilisation Verified (per Utilisation Summary): | B12: ='Utilisation Summary'!B14 -> 946590.9
A13: % of Disbursed Amount Utilised: | B13: ='Utilisation Summary'!D14 -> 1.0609127
A14: Number of Red-Flagged Transactions: | B14: =COUNTA('Diversion Red-Flag Log'!A4:A1000)-COUNTBLANK('Diversion Red-Flag Log'!A4:A1000) -> -995
A16: Finding: Based on the above review, the utilisation of loan proceeds is assessed as [Satisfactory / Requires Further Clarification / Diversion Suspected] — strike out as applicable.
A18: Remarks:
A21: Remarks Box:
A28: Verified By (Name & Designation):
A30: Signature & Date:
A32: Approved By (Credit Head):
A34: Signature & Date:

Sheet Dashboard
A1: END-USE MONITORING — SUMMARY DASHBOARD
A3: Borrower | B3: ='Loan Master'!B3 -> [Borrower Name — from KYC]
A4: Loan Type | B4: ='Loan Master'!B5 -> LAP
A5: Sanctioned Amount | B5: ='Loan Master'!B6 -> 892242
A6: Disbursed Amount | B6: ='Loan Master'!B9 -> 892242
A7: Disbursement Date | B7: ='Loan Master'!B8 -> 46129
A8: Total Utilised (window) | B8: ='Utilisation Summary'!B14 -> 946590.9
A9: % Utilised | B9: ='Utilisation Summary'!D14 -> 1.0609127
A10: Red-Flagged Transactions | B10: =COUNTIF('Txn Register (Auto)'!L:L,TRUE()) -> 1
A11: Red-Flagged Amount | B11: =SUMIF('Txn Register (Auto)'!L:L,TRUE(),'Txn Register (Auto)'!C:C) -> 200000
A12: Overall Status | B12: =IF(COUNTIF('Txn Register (Auto)'!L:L,TRUE())=0,"CLEAN","REVIEW REQUIRED") -> REVIEW REQUIRED
A15: Utilisation by End-Use Bucket
A16: ='Utilisation Summary'!A7 -> Bank Charges | B16: ='Utilisation Summary'!B7 -> 5.9
A17: ='Utilisation Summary'!A8 -> Cash Withdrawal | B17: ='Utilisation Summary'!B8 -> 226000
A18: ='Utilisation Summary'!A9 -> Debt Servicing (Existing Loans) | B18: ='Utilisation Summary'!B9 -> 55152
A19: ='Utilisation Summary'!A10 -> Household / Personal Spend | B19: ='Utilisation Summary'!B10 -> 2130.18
A20: ='Utilisation Summary'!A11 -> Incoming Funds / Not Applicable | B20: ='Utilisation Summary'!B11 -> 0
A21: ='Utilisation Summary'!A12 -> Investment / Gold Purchase | B21: ='Utilisation Summary'!B12 -> 660
A22: ='Utilisation Summary'!A13 -> Third-Party Transfer (Unverified) | B22: ='Utilisation Summary'!B13 -> 662642.82
